2020-07-12 20:58:15,082 ERROR: Exception on / [GET] [in /Users/cthepot/code/crypto_index/venv/lib/python3.7/site-packages/flask/app.py:1892]
Traceback (most recent call last):
  File "/Users/cthepot/code/crypto_index/venv/lib/python3.7/site-packages/sqlalchemy/engine/base.py", line 2339, in _wrap_pool_connect
    return fn()
  File "/Users/cthepot/code/crypto_index/venv/lib/python3.7/site-packages/sqlalchemy/pool/base.py", line 364, in connect
    return _ConnectionFairy._checkout(self)
  File "/Users/cthepot/code/crypto_index/venv/lib/python3.7/site-packages/sqlalchemy/pool/base.py", line 778, in _checkout
    fairy = _ConnectionRecord.checkout(pool)
  File "/Users/cthepot/code/crypto_index/venv/lib/python3.7/site-packages/sqlalchemy/pool/base.py", line 495, in checkout
    rec = pool._do_get()
  File "/Users/cthepot/code/crypto_index/venv/lib/python3.7/site-packages/sqlalchemy/pool/impl.py", line 140, in _do_get
    self._dec_overflow()
  File "/Users/cthepot/code/crypto_index/venv/lib/python3.7/site-packages/sqlalchemy/util/langhelpers.py", line 69, in __exit__
    exc_value, with_traceback=exc_tb,
  File "/Users/cthepot/code/crypto_index/venv/lib/python3.7/site-packages/sqlalchemy/util/compat.py", line 178, in raise_
    raise exception
  File "/Users/cthepot/code/crypto_index/venv/lib/python3.7/site-packages/sqlalchemy/pool/impl.py", line 137, in _do_get
    return self._create_connection()
  File "/Users/cthepot/code/crypto_index/venv/lib/python3.7/site-packages/sqlalchemy/pool/base.py", line 309, in _create_connection
    return _ConnectionRecord(self)
  File "/Users/cthepot/code/crypto_index/venv/lib/python3.7/site-packages/sqlalchemy/pool/base.py", line 440, in __init__
    self.__connect(first_connect_check=True)
  File "/Users/cthepot/code/crypto_index/venv/lib/python3.7/site-packages/sqlalchemy/pool/base.py", line 661, in __connect
    pool.logger.debug("Error on connect(): %s", e)
  File "/Users/cthepot/code/crypto_index/venv/lib/python3.7/site-packages/sqlalchemy/util/langhelpers.py", line 69, in __exit__
    exc_value, with_traceback=exc_tb,
  File "/Users/cthepot/code/crypto_index/venv/lib/python3.7/site-packages/sqlalchemy/util/compat.py", line 178, in raise_
    raise exception
  File "/Users/cthepot/code/crypto_index/venv/lib/python3.7/site-packages/sqlalchemy/pool/base.py", line 656, in __connect
    connection = pool._invoke_creator(self)
  File "/Users/cthepot/code/crypto_index/venv/lib/python3.7/site-packages/sqlalchemy/engine/strategies.py", line 114, in connect
    return dialect.connect(*cargs, **cparams)
  File "/Users/cthepot/code/crypto_index/venv/lib/python3.7/site-packages/sqlalchemy/engine/default.py", line 493, in connect
    return self.dbapi.connect(*cargs, **cparams)
  File "/Users/cthepot/code/crypto_index/venv/lib/python3.7/site-packages/psycopg2/__init__.py", line 127, in connect
    conn = _connect(dsn, connection_factory=connection_factory, **kwasync)
psycopg2.OperationalError: could not connect to server: No such file or directory
	Is the server running locally and accepting
	connections on Unix domain socket "/tmp/.s.PGSQL.5432"?


The above exception was the direct cause of the following exception:

Traceback (most recent call last):
  File "/Users/cthepot/code/crypto_index/venv/lib/python3.7/site-packages/flask/app.py", line 2447, in wsgi_app
    response = self.full_dispatch_request()
  File "/Users/cthepot/code/crypto_index/venv/lib/python3.7/site-packages/flask/app.py", line 1952, in full_dispatch_request
    rv = self.handle_user_exception(e)
  File "/Users/cthepot/code/crypto_index/venv/lib/python3.7/site-packages/flask/app.py", line 1821, in handle_user_exception
    reraise(exc_type, exc_value, tb)
  File "/Users/cthepot/code/crypto_index/venv/lib/python3.7/site-packages/flask/_compat.py", line 39, in reraise
    raise value
  File "/Users/cthepot/code/crypto_index/venv/lib/python3.7/site-packages/flask/app.py", line 1950, in full_dispatch_request
    rv = self.dispatch_request()
  File "/Users/cthepot/code/crypto_index/venv/lib/python3.7/site-packages/flask/app.py", line 1936, in dispatch_request
    return self.view_functions[rule.endpoint](**req.view_args)
  File "/Users/cthepot/code/crypto_index/app/routes.py", line 34, in index
    .paginate(page, app.config["ASSETS_PER_PAGE"], False)
  File "/Users/cthepot/code/crypto_index/venv/lib/python3.7/site-packages/flask_sqlalchemy/__init__.py", line 496, in paginate
    items = self.limit(per_page).offset((page - 1) * per_page).all()
  File "/Users/cthepot/code/crypto_index/venv/lib/python3.7/site-packages/sqlalchemy/orm/query.py", line 3341, in all
    return list(self)
  File "/Users/cthepot/code/crypto_index/venv/lib/python3.7/site-packages/sqlalchemy/orm/query.py", line 3503, in __iter__
    return self._execute_and_instances(context)
  File "/Users/cthepot/code/crypto_index/venv/lib/python3.7/site-packages/sqlalchemy/orm/query.py", line 3525, in _execute_and_instances
    querycontext, self._connection_from_session, close_with_result=True
  File "/Users/cthepot/code/crypto_index/venv/lib/python3.7/site-packages/sqlalchemy/orm/query.py", line 3540, in _get_bind_args
    mapper=self._bind_mapper(), clause=querycontext.statement, **kw
  File "/Users/cthepot/code/crypto_index/venv/lib/python3.7/site-packages/sqlalchemy/orm/query.py", line 3518, in _connection_from_session
    conn = self.session.connection(**kw)
  File "/Users/cthepot/code/crypto_index/venv/lib/python3.7/site-packages/sqlalchemy/orm/session.py", line 1141, in connection
    execution_options=execution_options,
  File "/Users/cthepot/code/crypto_index/venv/lib/python3.7/site-packages/sqlalchemy/orm/session.py", line 1147, in _connection_for_bind
    engine, execution_options
  File "/Users/cthepot/code/crypto_index/venv/lib/python3.7/site-packages/sqlalchemy/orm/session.py", line 433, in _connection_for_bind
    conn = bind._contextual_connect()
  File "/Users/cthepot/code/crypto_index/venv/lib/python3.7/site-packages/sqlalchemy/engine/base.py", line 2305, in _contextual_connect
    self._wrap_pool_connect(self.pool.connect, None),
  File "/Users/cthepot/code/crypto_index/venv/lib/python3.7/site-packages/sqlalchemy/engine/base.py", line 2343, in _wrap_pool_connect
    e, dialect, self
  File "/Users/cthepot/code/crypto_index/venv/lib/python3.7/site-packages/sqlalchemy/engine/base.py", line 1585, in _handle_dbapi_exception_noconnection
    sqlalchemy_exception, with_traceback=exc_info[2], from_=e
  File "/Users/cthepot/code/crypto_index/venv/lib/python3.7/site-packages/sqlalchemy/util/compat.py", line 178, in raise_
    raise exception
  File "/Users/cthepot/code/crypto_index/venv/lib/python3.7/site-packages/sqlalchemy/engine/base.py", line 2339, in _wrap_pool_connect
    return fn()
  File "/Users/cthepot/code/crypto_index/venv/lib/python3.7/site-packages/sqlalchemy/pool/base.py", line 364, in connect
    return _ConnectionFairy._checkout(self)
  File "/Users/cthepot/code/crypto_index/venv/lib/python3.7/site-packages/sqlalchemy/pool/base.py", line 778, in _checkout
    fairy = _ConnectionRecord.checkout(pool)
  File "/Users/cthepot/code/crypto_index/venv/lib/python3.7/site-packages/sqlalchemy/pool/base.py", line 495, in checkout
    rec = pool._do_get()
  File "/Users/cthepot/code/crypto_index/venv/lib/python3.7/site-packages/sqlalchemy/pool/impl.py", line 140, in _do_get
    self._dec_overflow()
  File "/Users/cthepot/code/crypto_index/venv/lib/python3.7/site-packages/sqlalchemy/util/langhelpers.py", line 69, in __exit__
    exc_value, with_traceback=exc_tb,
  File "/Users/cthepot/code/crypto_index/venv/lib/python3.7/site-packages/sqlalchemy/util/compat.py", line 178, in raise_
    raise exception
  File "/Users/cthepot/code/crypto_index/venv/lib/python3.7/site-packages/sqlalchemy/pool/impl.py", line 137, in _do_get
    return self._create_connection()
  File "/Users/cthepot/code/crypto_index/venv/lib/python3.7/site-packages/sqlalchemy/pool/base.py", line 309, in _create_connection
    return _ConnectionRecord(self)
  File "/Users/cthepot/code/crypto_index/venv/lib/python3.7/site-packages/sqlalchemy/pool/base.py", line 440, in __init__
    self.__connect(first_connect_check=True)
  File "/Users/cthepot/code/crypto_index/venv/lib/python3.7/site-packages/sqlalchemy/pool/base.py", line 661, in __connect
    pool.logger.debug("Error on connect(): %s", e)
  File "/Users/cthepot/code/crypto_index/venv/lib/python3.7/site-packages/sqlalchemy/util/langhelpers.py", line 69, in __exit__
    exc_value, with_traceback=exc_tb,
  File "/Users/cthepot/code/crypto_index/venv/lib/python3.7/site-packages/sqlalchemy/util/compat.py", line 178, in raise_
    raise exception
  File "/Users/cthepot/code/crypto_index/venv/lib/python3.7/site-packages/sqlalchemy/pool/base.py", line 656, in __connect
    connection = pool._invoke_creator(self)
  File "/Users/cthepot/code/crypto_index/venv/lib/python3.7/site-packages/sqlalchemy/engine/strategies.py", line 114, in connect
    return dialect.connect(*cargs, **cparams)
  File "/Users/cthepot/code/crypto_index/venv/lib/python3.7/site-packages/sqlalchemy/engine/default.py", line 493, in connect
    return self.dbapi.connect(*cargs, **cparams)
  File "/Users/cthepot/code/crypto_index/venv/lib/python3.7/site-packages/psycopg2/__init__.py", line 127, in connect
    conn = _connect(dsn, connection_factory=connection_factory, **kwasync)
sqlalchemy.exc.OperationalError: (psycopg2.OperationalError) could not connect to server: No such file or directory
	Is the server running locally and accepting
	connections on Unix domain socket "/tmp/.s.PGSQL.5432"?

(Background on this error at: http://sqlalche.me/e/13/e3q8)
2020-07-12 21:01:22,354 INFO: CIF startup [in /Users/cthepot/code/crypto_index/app/__init__.py:53]
2020-07-12 21:53:15,643 INFO: CIF startup [in /Users/cthepot/code/crypto_index/app/__init__.py:53]
2020-07-12 21:53:30,001 INFO: CIF startup [in /Users/cthepot/code/crypto_index/app/__init__.py:53]
